Workbook

Sheet Overview
A1: TRIBE DIGITAL BOILER MODEL
A2: Economic model for modular data centre heat recovery
A3: Version 3.1 - Dynamic Capex | January 2026
A5: HOW TO USE THIS MODEL
A7: Step 1 | B7: Configure Hardware | C7: Go to '0. Rack Profile' and select your chipset (dropdown in B6) and cooling method (dropdown in B17). Optionally adjust the module IT capacity target (B36).
A8: Step 2 | B8: Review Module Specs | C8: Check '1. Module Criteria' to see the resulting module specifications. Enable/disable heat pump (B15) and set output temperature if needed.
A9: Step 3 | B9: Check Capex | C9: Review '2. Module Capex' - costs are calculated automatically from your hardware choices. Adjust Reference Data rates if needed.
A10: Step 4 | B10: Select Customer Process | C10: Go to '5. Buyer Profile' and select an industrial process from the dropdown (B11). The model calculates how many modules are needed.
A11: Step 5 | B11: Review System Economics | C11: Check '6. System Capex' for total investment, '9. System P&L' for revenue and profit analysis.
A12: Step 6 | B12: Adjust Assumptions | C12: Fine-tune costs in '11. Reference Data' (yellow cells). All downstream calculations update automatically.
A14: MODEL STRUCTURE
A16: Sheet | B16: Purpose | C16: Key Features
A17: 0. Rack Profile | B17: Hardware config | C17: Chipset, cooling method, rack density, heat capture
A18: 1. Module Criteria | B18: Module specs | C18: Heat pump config, thermal output, heat pricing
A19: 2. Module Capex | B19: Module capital cost | C19: Dynamic from Rack Profile - enclosure, cooling, power, thermal, monitoring
A20: 3. Module Opex | B20: Module operating cost | C20: Electricity, maintenance, insurance
A21: 4. Module Flow | B21: Module hydraulics | C21: Flow rates, pipe sizing
A22: 5. Buyer Profile | B22: Customer matching | C22: Process selection, modules required, heat balance, rejection sizing
A23: 6. System Capex | B23: System capital | C23: Total investment including rejection equipment
A24: 7. System Opex | B24: System operating cost | C24: Including rejection running costs
A25: 8. System Flow | B25: System hydraulics | C25: Supply vs demand, utilisation, constraints
A26: 9. System P&L | B26: Profit & loss | C26: Revenue (compute + heat), costs, margins, payback
A27: 11. Reference Data | B27: Lookup tables | C27: Hardware costs, chipset specs, rejection rates, process ΔT
A28: 12. Process Library | B28: Process database | C28: 42 industrial heat processes with source citations
A30: KEY CONCEPTS
A32: BYOGPU Model | B32: Customers bring their own GPUs - capex covers infrastructure only, not compute hardware
A33: Thermal vs Flow | B33: Low ΔT processes become flow-constrained, needing more modules than thermal demand alone
A34: Heat Rejection | B34: Equipment sized for 100% rejection (buyer offline); opex based on actual excess
A35: Cooling Premium | B35: DTC +15%, Single-phase immersion +25%, Two-phase +40% vs air-cooled
A36: Dynamic Capex | B36: Module costs auto-calculate from Rack Profile - change chipset/cooling, capex updates
A38: DATA FLOW
A40: Rack Profile → Module Criteria → Module Capex/Opex → Buyer Profile → System Capex/Opex/P&L
A42: INPUT CONVENTIONS
A44: Yellow cells | B44: Example | C44: Adjustable inputs - safe to modify
A45: Blue headers | B45: Example | C45: Section headers - do not edit
A46: White cells | B46: Example | C46: Calculated values - do not edit
A48: KEY INPUTS QUICK REFERENCE
A50: Location | B50: Input | C50: Options
A51: Rack Profile B6 | B51: Chipset | C51: NVIDIA H100/H200/B200, AMD MI300X, Intel Gaudi 3
A52: Rack Profile B17 | B52: Cooling method | C52: DTC, Single-Phase Immersion, Two-Phase Immersion, RDHX
...

Sheet Agent Context
A1: AGENT CONTEXT
A2: Context and guidelines for AI agents working on this model
A4: BUSINESS CONTEXT
A6: Business Model | B6: TRIBE operates 'digital boilers' - modular data centres co-located on industrial sites that capture waste heat from GPU compute and sell it to industrial partners.
A7: BYOGPU | B7: Customers bring their own GPUs - TRIBE provides infrastructure only. Capex excludes compute hardware costs.
A8: Heat Capture | B8: Liquid cooling (DTC or immersion) captures 75-98% of server waste heat at 45-57°C. Heat pumps lift this to 70-90°C for industrial use.
A9: Revenue Streams | B9: 1) Compute hosting fees (£/kW/month), 2) Heat sales to industrial buyer (£/MWh)
A10: Target Customers | B10: Industrial processes requiring low-grade heat: pasteurisation, CIP systems, district heating, commercial laundry, swimming pools, HVAC
A12: MODEL ARCHITECTURE
A14: Data Flow | B14: Rack Profile → Module Criteria → Module Capex/Opex/Flow → Buyer Profile → System Capex/Opex/Flow/P&L
A15: Rack Profile | B15: INPUTS: Chipset (dropdown B6), Cooling method (dropdown B17), Module IT target (B36). OUTPUTS: Rack density, heat capture rate, capex premium.
A16: Module Criteria | B16: INPUTS: Heat pump toggle (B15), HP output temp (B16), Heat pricing (B27-B29). OUTPUTS: Per-module thermal output, COP.
A17: Module Capex | B17: DYNAMIC CALCULATION from Rack Profile. References costs in '11. Reference Data' rows 71-105. Conditional DTC vs Immersion blocks.
A18: Buyer Profile | B18: INPUT: Process selection dropdown (B11) from Process Library. OUTPUTS: Modules required, binding constraint (thermal vs flow), heat rejection sizing.
A19: System Sheets | B19: Aggregate module-level calculations × number of modules. Add shared infrastructure, rejection equipment, integration costs.
A20: Reference Data | B20: LOOKUP TABLES: Rejection infrastructure (rows 9-16), Cooling characteristics (rows 22-27), Chipsets (rows 33-38), Hardware capex (rows 71-105).
A21: Process Library | B21: DATABASE of 42 industrial processes with temp, thermal load, operating hours, ΔT, source citations. Feeds Buyer Profile dropdown.
A23: KEY TECHNICAL CONCEPTS
A25: Thermal vs Flow Constraint | B25: Low ΔT processes (e.g. pasteurisation, 5°C) become FLOW-constrained - need more modules than thermal demand alone. High ΔT processes (e.g. district heating, 30°C) are THERMAL-constrained.
A26: Heat Pump Thermodynamics | B26: Q_hot = Q_cold × COP/(COP-1). Electrical input = Q_hot/COP. COP decreases with higher temperature lift (source→sink).
A27: Heat Rejection Sizing | B27: CAPEX sized for 100% rejection (worst case - buyer goes offline). OPEX based on ACTUAL excess heat during normal operation.
A28: Cooling Method Trade-offs | B28: DTC: 75% capture, 57.5°C, +15% capex, larger footprint. Immersion: 95-98% capture, 50-55°C, +25-40% capex, denser packing.
A29: Rack Thermal Limits | B29: DTC: 80kW/rack, Single-phase immersion: 100kW/rack, Two-phase: 120kW/rack. Determines GPU density and module footprint.
A31: FORMULA CONVENTIONS
A33: Cross-sheet references | B33: Use full sheet names in quotes, e.g. ='0. Rack Profile'!B37
A34: Conditional blocks | B34: DTC vs Immersion costs use IF(B6="Direct-to-Chip (DTC)",...) pattern
A35: Unit conversions | B35: kWh to MWh: divide by 1000. Annual hours: 8760. Heat: kWth (thermal kilowatts).
A36: Currency | B36: All values in GBP (£). Format: £#,##0 for whole numbers, £#,##0.00 for decimals.
A37: Percentages | B37: Store as decimals (0.15 not 15%), format as 0.0% for display.
A39: KEY CELL REFERENCES
A41: Cell | B41: Description | C41: Notes
A42: 0. Rack Profile!B6 | B42: Chipset selection (dropdown) | C42: Drives TDP, density, cost assumptions
A43: 0. Rack Profile!B17 | B43: Cooling method selection (dropdown) | C43: Drives heat capture rate, PUE, capex, source ΔT
A44: 0. Rack Profile!B23 | B44: PUE by cooling method | C44: From Reference Data lookup. Drives infrastructure power.
A45: 0. Rack Profile!B37 | B45: Racks per module | C45: Calculated from space constraints
A46: 0. Rack Profile!B40 | B46: Module IT capacity (kW) | C46: TDP × racks per module
A47: 0. Rack Profile!B43 | B47: Captured heat (kWth) | C47: IT capacity × heat capture rate
A49: 1. Module Criteria!B15 | B49: Heat pump enabled (1/0) | C49: Toggles HP capex/opex calculations
A50: 1. Module Criteria!B16 | B50: Heat pump output temp (°C) | C50: Input for COP calculation
A51: 1. Module Criteria!B17 | B51: COP (Carnot-based) | C51: 0.5×(T_out+273)/ΔT lift. Dynamic by temps.
...

Sheet 0. Rack Profile
A1: RACK PROFILE | F1: Intent | G1: Explanation | H1: Dependents
A2: Define module hardware configuration - chipset and cooling approach | F2: Define GPU hardware to determine power and cooling requirements | G2: Row label only
A4: CHIPSET CONFIGURATION
A6: Chipset type | B6: NVIDIA H100 | F6: Define GPU hardware to determine power and cooling requirements | G6: Text value for Chipset type | H6: 0. Rack Profile!B9 - TDP per chip (W); 0. Rack Profile!B10 - Chips per server; 0. Rack Profile!B12 - Max junction temp (°C); 2. Module Capex!B5 - Chipset; 5. Buyer Profile!B5 - Chipset; 6. System Capex!B5 - Chipset; 7. System Opex!B5 - Chipset; 8. System Flow!B5 - Chipset; 9. System P&L!B8 - Chipset
A8: Chipset Specifications | F8: Define GPU hardware to determine power and cooling requirements | G8: Row label only
A9: TDP per chip (W) | B9: =IF(B6="NVIDIA H100",700,IF(B6="NVIDIA H200",700,IF(B6="NVIDIA B200",1000,IF(B6="AMD MI300X",750,IF(B6="Intel Gaudi 3",600,500))))) | C9: Thermal Design Power | F9: Establish base power draw for thermal calculations | G9: Conditional logic for TDP per chip (W) | H9: 0. Rack Profile!B11 - Server power (kW)
A10: Chips per server | B10: =IF(B6="NVIDIA H100",8,IF(B6="NVIDIA H200",8,IF(B6="NVIDIA B200",8,IF(B6="AMD MI300X",8,IF(B6="Intel Gaudi 3",8,8))))) | C10: Typical GPU count per node | F10: Configure server density for rack power calculations | G10: Conditional logic for Chips per server | H10: 0. Rack Profile!B11 - Server power (kW); 0. Rack Profile!B30 - GPUs per rack
A11: Server power (kW) | B11: =B9*B10/1000*1.15 | C11: Chip TDP × count × 1.15 (overhead) | F11: Calculate total server power including overhead for sizing | G11: Calculated from upstream values for Server power (kW) | H11: 0. Rack Profile!B29 - Servers per rack; 0. Rack Profile!B31 - Actual rack power (kW)
A12: Max junction temp (°C) | B12: =IF(B6="NVIDIA H100",83,IF(B6="NVIDIA H200",83,IF(B6="NVIDIA B200",85,IF(B6="AMD MI300X",90,IF(B6="Intel Gaudi 3",95,85))))) | C12: Chip thermal limit | F12: Define thermal limits to ensure safe GPU operation | G12: Conditional logic for Max junction temp (°C) | H12: 0. Rack Profile!B13 - Recommended coolant inlet (°C)
A13: Recommended coolant inlet (°C) | B13: =B12-25 | C13: Target 25°C below Tj max | F13: Set cooling system design temperature | G13: Calculated from upstream values for Recommended coolant inlet (°C)
A15: COOLING APPROACH
A17: Cooling method | B17: Direct-to-Chip (DTC) | F17: Select cooling technology to determine heat capture and costs | G17: Text value for Cooling method | H17: 0. Rack Profile!B20 - Heat capture rate (%); 0. Rack Profile!B21 - Capture temperature (°C); 0. Rack Profile!B22 - Coolant type; 0. Rack Profile!B23 - PUE contribution; 0. Rack Profile!B24 - Capex premium vs air-cooled (%); 0. Rack Profile!B25 - Rack thermal limit (kW/rack); 2. Module Capex!B6 - Cooling method; 4. Module Flow!B11 - Source loop ΔT (°C); 5. Buyer Profile!B6 - Cooling method; 6. System Capex!B6 - Cooling method; ... and 3 more
A19: Cooling Method Characteristics | F19: Select cooling technology to determine heat capture and costs | G19: Row label only
A20: Heat capture rate (%) | B20: =IF(B17="Direct-to-Chip (DTC)",0.75,IF(B17="Single-Phase Immersion",0.95,IF(B17="Two-Phase Immersion",0.98,IF(B17="Rear Door Heat Exchanger",0.5,0.05)))) | C20: Fraction of IT heat captured to liquid | F20: Quantify recoverable heat for revenue calculations | G20: Conditional logic for Heat capture rate (%) | H20: 0. Rack Profile!B43 - Captured heat (kWth); 0. Rack Profile!B45 - Residual heat to air (kWth); 0. Rack Profile!B63 - Total heat output (per kW IT); 1. Module Criteria!B10 - Heat capture rate (%)
A21: Capture temperature (°C) | B21: =IF(B17="Direct-to-Chip (DTC)",57.5,IF(B17="Single-Phase Immersion",50,IF(B17="Two-Phase Immersion",55,IF(B17="Rear Door Heat Exchanger",45,35)))) | C21: Typical coolant outlet temperature | F21: Determine heat quality for buyer matching | G21: Conditional logic for Capture temperature (°C) | H21: 0. Rack Profile!B44 - Capture temperature (°C); 0. Rack Profile!B49 - Heat capture quality; 0. Rack Profile!B50 - Heat pump requirement; 0. Rack Profile!B51 - Recommended HP output (°C); 0. Rack Profile!B52 - Estimated COP at recommended output; 0. Rack Profile!B60 - Temperature lift (K); 1. Module Criteria!B12 - Capture temperature (°C); 8. System Flow!B7 - Capture temperature (°C)
A22: Coolant type | B22: =IF(B17="Direct-to-Chip (DTC)","Water/Glycol",IF(B17="Single-Phase Immersion","Dielectric fluid",IF(B17="Two-Phase Immersion","Fluorocarbon",IF(B17="Rear Door Heat Exchanger","Water/Glycol","Air")))) | F22: Specify fluid for equipment selection | G22: Conditional logic for Coolant type
A23: PUE contribution | B23: =IF(B17="Direct-to-Chip (DTC)",1.05,IF(B17="Single-Phase Immersion",1.03,IF(B17="Two-Phase Immersion",1.02,IF(B17="Rear Door Heat Exchanger",1.1,1.4)))) | C23: Cooling system efficiency factor | F23: Model infrastructure efficiency for opex calculations | G23: Conditional logic for PUE contribution | H23: 3. Module Opex!B6 - Infrastructure power (from PUE)
A24: Capex premium vs air-cooled (%) | B24: =IF(B17="Direct-to-Chip (DTC)",15,IF(B17="Single-Phase Immersion",25,IF(B17="Two-Phase Immersion",40,IF(B17="Rear Door Heat Exchanger",10,0)))) | F24: Account for cooling technology cost differences | G24: Conditional logic for Capex premium vs air-cooled (%) | H24: 2. Module Capex!B59 - Premium rate (%)
A25: Rack thermal limit (kW/rack) | B25: =IF(B17="Direct-to-Chip (DTC)",80,IF(B17="Single-Phase Immersion",100,IF(B17="Two-Phase Immersion",120,IF(B17="Rear Door Heat Exchanger",40,20)))) | C25: Max power per 42U rack | F25: Set rack density constraint for module sizing | G25: Conditional logic for Rack thermal limit (kW/rack) | H25: 0. Rack Profile!B29 - Servers per rack; 0. Rack Profile!B32 - Rack thermal utilisation (%)
A27: RACK CONFIGURATION
A29: Servers per rack | B29: =ROUNDDOWN(B25/B11,0) | C29: Rack thermal limit ÷ server power | F29: Calculate achievable density within thermal limits | G29: Rounded calculation for Servers per rack | H29: 0. Rack Profile!B30 - GPUs per rack; 0. Rack Profile!B31 - Actual rack power (kW); 0. Rack Profile!B38 - Servers per module
A30: GPUs per rack | B30: =B29*B10 | C30: Servers per rack × chips per server | F30: Compute total GPU capacity per rack | G30: Calculated from upstream values for GPUs per rack | H30: 0. Rack Profile!B39 - GPUs per module
A31: Actual rack power (kW) | B31: =B29*B11 | C31: May be less than thermal limit | F31: Determine actual power for infrastructure sizing | G31: Calculated from upstream values for Actual rack power (kW) | H31: 0. Rack Profile!B32 - Rack thermal utilisation (%); 0. Rack Profile!B37 - Racks per module; 0. Rack Profile!B40 - Actual module IT capacity (kW)
A32: Rack thermal utilisation (%) | B32: =B31/B25 | C32: Actual vs limit | F32: Assess how well rack capacity is used | G32: Calculated from upstream values for Rack thermal utilisation (%)
A34: MODULE SUMMARY
A36: Module IT capacity target (kW) | B36: 250 | C36: Design target - adjust as needed | F36: Define standardised module size for business model | G36: Input parameter: Module IT capacity target (kW) | H36: 0. Rack Profile!B37 - Racks per module
A37: Racks per module | B37: =ROUNDUP(B36/B31,0) | C37: To meet capacity target | F37: Calculate rack count to meet module capacity target | G37: Rounded calculation for Racks per module | H37: 0. Rack Profile!B38 - Servers per module; 0. Rack Profile!B39 - GPUs per module; 0. Rack Profile!B40 - Actual module IT capacity (kW); 2. Module Capex!B7 - Racks per module
A38: Servers per module | B38: =B37*B29 | F38: Aggregate compute capacity at module level | G38: Calculated from upstream values for Servers per module | H38: 2. Module Capex!B8 - Servers per module
A39: GPUs per module | B39: =B37*B30 | F39: Aggregate compute capacity at module level | G39: Calculated from upstream values for GPUs per module | H39: 2. Module Capex!B69 - Capex per GPU (£/GPU); 5. Buyer Profile!B7 - GPUs per module; 6. System Capex!B7 - GPUs per module; 7. System Opex!B7 - GPUs per module
A40: Actual module IT capacity (kW) | B40: =B37*B31 | C40: May differ slightly from target | F40: Define standardised module size for business model | G40: Calculated from upstream values for Actual module IT capacity (kW) | H40: 0. Rack Profile!B43 - Captured heat (kWth); 0. Rack Profile!B45 - Residual heat to air (kWth); 0. Rack Profile!B68 - Heat delivered (MWh/yr); 1. Module Criteria!B5 - Module IT capacity (kW); 2. Module Capex!B9 - Module IT capacity (kW); 5. Buyer Profile!B8 - Module IT capacity (kW); 6. System Capex!B48 - Capex per IT kW (£/kW)
A42: Heat Output | F42: Calculate annual heat sales volume
A43: Captured heat (kWth) | B43: =B40*B20 | C43: Available for heat recovery | F43: Calculate heat available for sale to buyers | G43: Calculated from upstream values for Captured heat (kWth) | H43: 0. Rack Profile!B69 - HP electricity (MWh/yr); 2. Module Capex!B10 - Captured heat (kWth)
A44: Capture temperature (°C) | B44: =B21 | F44: Determine heat quality for buyer matching | G44: Formula: Capture temperature (°C)
A45: Residual heat to air (kWth) | B45: =B40*(1-B20) | C45: Requires conventional cooling | F45: Identify heat requiring rejection (cost) | G45: Calculated from upstream values for Residual heat to air (kWth)
A47: HEAT RECOVERY ASSESSMENT
A49: Heat capture quality | B49: =IF(B21>=55,"HIGH - Suitable for process heat",IF(B21>=45,"MEDIUM - District heating suitable","LOW - Limited applications")) | F49: Classify heat grade for buyer matching | G49: Conditional logic for Heat capture quality
A50: Heat pump requirement | B50: =IF(B21>=70,"Optional - direct use possible",IF(B21>=50,"Recommended for industrial use","Required for most applications")) | F50: Determine if temperature boost needed for applications | G50: Conditional logic for Heat pump requirement | H50: 0. Rack Profile!B52 - Estimated COP at recommended output
A51: Recommended HP output (°C) | B51: =IF(B21>=70,B21,IF(B21>=50,90,80)) | F51: Model parameter | G51: Conditional logic for Recommended HP output (°C) | H51: 0. Rack Profile!B52 - Estimated COP at recommended output; 0. Rack Profile!B57 - Target output temperature (°C)
A52: Estimated COP at recommended output | B52: =IF(B50="Optional - direct use possible","-",MAX('11. Reference Data'!B111,MIN('11. Reference Data'!B112,ROUND('11. Reference Data'!B110*(B51+273.15)/(B51-B21),2)))) | C52: Carnot-based estimate | F52: Calculate heat pump efficiency for economics | G52: Conditional logic for Estimated COP at recommended output
A54: HEAT PUMP ECONOMICS
...

Sheet 1. Module Criteria
A1: MODULE CRITERIA | F1: Intent | G1: Explanation | H1: Dependents
A2: Hardware specifications and configuration for a single digital boiler module | F2: Model parameter | G2: Row label only
A4: COMPUTE SPECIFICATIONS
A5: Module IT capacity (kW) | B5: ='0. Rack Profile'!B40 | C5: From Rack Profile (actual) | D5: Standard MDC module size | F5: Pull standardised module size for consistent sizing | G5: Pulls value from 0. Rack Profile!B40 | H5: 1. Module Criteria!B11 - Captured heat (kWth); 3. Module Opex!B7 - Infrastructure power cost (£/yr); 5. Buyer Profile!B65 - Total IT capacity (kW); 9. System P&L!B12 - Module IT capacity (kW)
A6: Compute rate (£/kW/month) | B6: 150 | D6: Colocation pricing | F6: Financial input or calculation | G6: Input parameter: Compute rate (£/kW/month) | H6: 9. System P&L!B13 - Rack rate (£/kW/month)
A7: Target utilisation rate (%) | B7: 0.9 | D7: Steady-state capacity utilisation | F7: Model realistic capacity usage for revenue | G7: Input parameter: Target utilisation rate (%) | H7: 1. Module Criteria!B24 - Annual heat output (MWh); 3. Module Opex!B7 - Infrastructure power cost (£/yr); 3. Module Opex!B9 - Heat pump electricity (£/yr); 5. Buyer Profile!B92 - Cooling infrastructure (kW); 9. System P&L!B15 - Utilisation assumption (%)
A9: HEAT CAPTURE SPECIFICATIONS
A10: Heat capture rate (%) | B10: ='0. Rack Profile'!B20 | C10: From Rack Profile (cooling method) | D10: % of IT load captured via DTC cooling | F10: Reference thermal specifications from rack design | G10: Pulls value from 0. Rack Profile!B20 | H10: 1. Module Criteria!B11 - Captured heat (kWth)
A11: Captured heat (kWth) | B11: =B5*B10 | D11: Thermal output without heat pump | F11: Power or thermal capacity metric | G11: Calculated from upstream values for Captured heat (kWth) | H11: 1. Module Criteria!B18 - Heat pump capacity (kWth); 1. Module Criteria!B21 - Thermal output (kWth); 4. Module Flow!B9 - Thermal power (kWth)
A12: Capture temperature (°C) | B12: ='0. Rack Profile'!B21 | C12: From Rack Profile (cooling method) | D12: DTC cooling loop output temperature | F12: Temperature parameter for thermal design | G12: Pulls value from 0. Rack Profile!B21 | H12: 1. Module Criteria!B17 - Heat pump COP; 1. Module Criteria!B22 - Delivery temperature (°C); 4. Module Flow!B10 - Inlet temperature (°C); 5. Buyer Profile!B69 - Heat pump required?; 5. Buyer Profile!B70 - Temperature lift required (K)
A14: HEAT PUMP CONFIGURATION
A15: Heat pump enabled? | B15: 1 | D15: 1 = Yes, 0 = No | F15: Toggle heat pump for scenario analysis | G15: Flag enabled for Heat pump enabled? | H15: 1. Module Criteria!B17 - Heat pump COP; 1. Module Criteria!B21 - Thermal output (kWth); 1. Module Criteria!B22 - Delivery temperature (°C); 1. Module Criteria!B29 - Effective heat price (£/MWh); 2. Module Capex!B53 - Heat pump unit; 2. Module Capex!B54 - Heat pump installation; 2. Module Capex!B55 - Heat pump controls; 3. Module Opex!B9 - Heat pump electricity (£/yr); 3. Module Opex!B18 - Heat pump maintenance (£/yr)
A16: Heat pump output temperature (°C) | B16: 90 | D16: Delivery temperature to industrial partner | F16: Temperature parameter for thermal design | G16: Input parameter: Heat pump output temperature (°C) | H16: 1. Module Criteria!B17 - Heat pump COP; 1. Module Criteria!B22 - Delivery temperature (°C)
A17: Heat pump COP | B17: =IF(B15=0,"-",MAX('11. Reference Data'!B111,MIN('11. Reference Data'!B112,ROUND('11. Reference Data'!B110*(B16+273.15)/(B16-B12),2)))) | D17: Carnot-based: η × T_hot(K) / ΔT | F17: Calculate heat pump efficiency at operating conditions | G17: Conditional logic for Heat pump COP | H17: 1. Module Criteria!B21 - Thermal output (kWth); 3. Module Opex!B9 - Heat pump electricity (£/yr); 5. Buyer Profile!B73 - HP electrical demand (kW)
A18: Heat pump capacity (kWth) | B18: =B11 | D18: Sized to captured heat | F18: Define or calculate system capability | G18: Formula: Heat pump capacity (kWth) | H18: 2. Module Capex!B53 - Heat pump unit; 5. Buyer Profile!B72 - Total HP capacity (kWth)
A20: MODULE OUTPUT SUMMARY
A21: Thermal output (kWth) | B21: =IF(B15=1,IF(B17<=1,B11,B11*B17/(B17-1)),B11) | D21: With HP: includes compressor work (COP protected) | F21: Calculate total heat delivery including HP boost | G21: Conditional logic for Thermal output (kWth) | H21: 1. Module Criteria!B24 - Annual heat output (MWh); 3. Module Opex!B9 - Heat pump electricity (£/yr); 4. Module Flow!B19 - Thermal power delivered (kWth); 5. Buyer Profile!B28 - Module thermal capacity (kWth)
A22: Delivery temperature (°C) | B22: =IF(B15=1,B16,B12) | F22: Set required output temperature for buyer | G22: Conditional logic for Delivery temperature (°C) | H22: 4. Module Flow!B20 - Outlet temperature (°C); 5. Buyer Profile!B29 - Module delivery temp (°C); 8. System Flow!B20 - Delivery temperature (°C)
A23: Hours per year | B23: 8760 | D23: 24/7 operation | F23: Model parameter | G23: Input assumption: Hours per year | H23: 1. Module Criteria!B24 - Annual heat output (MWh); 3. Module Opex!B7 - Infrastructure power cost (£/yr); 3. Module Opex!B9 - Heat pump electricity (£/yr)
A24: Annual heat output (MWh) | B24: =B21*B23*B7/1000 | F24: Convert to annual volume for revenue calculation | G24: Calculated from upstream values for Annual heat output (MWh)
A26: HEAT PRICING
A27: Base heat price - no HP (£/MWh) | B27: 25 | D27: Low-temp heat (55-60°C) | F27: Set heat sales price assumption | G27: Input parameter: Base heat price - no HP (£/MWh) | H27: 1. Module Criteria!B29 - Effective heat price (£/MWh)
A28: Premium heat price - with HP (£/MWh) | B28: 40 | D28: High-temp heat (90°C) | F28: Set heat sales price assumption | G28: Input parameter: Premium heat price - with HP (£/MWh) | H28: 1. Module Criteria!B29 - Effective heat price (£/MWh)
A29: Effective heat price (£/MWh) | B29: =IF(B15=1,B28,B27) | F29: Set heat sales price assumption | G29: Conditional logic for Effective heat price (£/MWh) | H29: 9. System P&L!B20 - Heat price (£/MWh)
A30: Reference: Industrial gas price (£/MWh) | B30: 53 | D30: UK industrial gas benchmark | F30: Financial input or calculation | G30: Input parameter: Reference: Industrial gas price (£/MWh)

Sheet 2. Module Capex
A1: MODULE CAPEX | F1: Intent | G1: Explanation | H1: Dependents
A2: Capital expenditure for a single digital boiler module | B2: Calculated dynamically from Rack Profile inputs | F2: Model parameter | G2: Text value for Capital expenditure for a single digital boiler module
A4: CONFIGURATION SUMMARY
A5: Chipset | B5: ='0. Rack Profile'!B6 | F5: Model parameter | G5: Pulls value from 0. Rack Profile!B6
A6: Cooling method | B6: ='0. Rack Profile'!B17 | F6: Model parameter | G6: Pulls value from 0. Rack Profile!B17 | H6: 2. Module Capex!B19 - Cold plate kits; 2. Module Capex!B20 - CDU (base); 2. Module Capex!B21 - CDU (capacity scaling); 2. Module Capex!B22 - Manifolds & quick-connects; 2. Module Capex!B23 - Primary loop piping; 2. Module Capex!B27 - Immersion tanks; 2. Module Capex!B28 - Dielectric fluid (initial fill); 2. Module Capex!B29 - Fluid management system
A7: Racks per module | B7: ='0. Rack Profile'!B37 | F7: Model parameter | G7: Pulls value from 0. Rack Profile!B37 | H7: 2. Module Capex!B15 - Rack enclosures; 2. Module Capex!C15 - Rack enclosures; 2. Module Capex!B27 - Immersion tanks; 2. Module Capex!B28 - Dielectric fluid (initial fill); 2. Module Capex!B33 - Rack PDUs; 2. Module Capex!B47 - Per-rack monitoring
A8: Servers per module | B8: ='0. Rack Profile'!B38 | F8: Model parameter | G8: Pulls value from 0. Rack Profile!B38 | H8: 2. Module Capex!B19 - Cold plate kits; 2. Module Capex!B22 - Manifolds & quick-connects
A9: Module IT capacity (kW) | B9: ='0. Rack Profile'!B40 | F9: Define or calculate system capability | G9: Pulls value from 0. Rack Profile!B40 | H9: 2. Module Capex!B21 - CDU (capacity scaling); 2. Module Capex!B34 - Module power distribution; 2. Module Capex!B68 - Capex per IT kW (£/kW)
A10: Captured heat (kWth) | B10: ='0. Rack Profile'!B43 | F10: Power or thermal capacity metric | G10: Pulls value from 0. Rack Profile!B43 | H10: 2. Module Capex!B40 - Heat exchanger (capacity scaling)
A12: ENCLOSURE & STRUCTURE
A13: Container shell | B13: ='11. Reference Data'!B71 | C13: Fixed per module | F13: Cost modular enclosure structure | G13: Pulls value from 11. Reference Data!B71 | H13: 2. Module Capex!B16 - SUBTOTAL: ENCLOSURE
A14: Container fit-out | B14: ='11. Reference Data'!B72 | C14: Fixed per module | F14: Cost modular enclosure structure | G14: Pulls value from 11. Reference Data!B72
A15: Rack enclosures | B15: =B7*'11. Reference Data'!B73 | C15: =B7&" racks × £"&'11. Reference Data'!B73 | F15: Cost per-rack housing | G15: Calculated from upstream values for Rack enclosures | H15: 2. Module Capex!B16 - SUBTOTAL: ENCLOSURE
A16: SUBTOTAL: ENCLOSURE | B16: =SUM(B13:B15) | F16: Subtotal enclosure costs for module | G16: Sum of component values for SUBTOTAL: ENCLOSURE | H16: 2. Module Capex!B60 - Applied to base infrastructure; 2. Module Capex!B63 - Base infrastructure; 6. System Capex!B14 - Enclosure & structure
A18: DTC COOLING | B18: Applies when cooling method = DTC | F18: Section for DTC-specific equipment | G18: Section header
A19: Cold plate kits | B19: =IF(B6="Direct-to-Chip (DTC)",B8*'11. Reference Data'!B76,0) | C19: Servers × £250/server | F19: Cost DTC cooling hardware per server | G19: Conditional logic for Cold plate kits | H19: 2. Module Capex!B24 - SUBTOTAL: DTC COOLING
A20: CDU (base) | B20: =IF(B6="Direct-to-Chip (DTC)",'11. Reference Data'!B77,0) | C20: Fixed per module | F20: Cost coolant distribution unit | G20: Conditional logic for CDU (base)
A21: CDU (capacity scaling) | B21: =IF(B6="Direct-to-Chip (DTC)",B9*'11. Reference Data'!B78,0) | C21: IT kW × £80/kW | F21: Cost coolant distribution unit | G21: Conditional logic for CDU (capacity scaling)
A22: Manifolds & quick-connects | B22: =IF(B6="Direct-to-Chip (DTC)",B8*'11. Reference Data'!B79,0) | C22: Servers × £150/server | F22: Cost fluid distribution to racks | G22: Conditional logic for Manifolds & quick-connects
A23: Primary loop piping | B23: =IF(B6="Direct-to-Chip (DTC)",'11. Reference Data'!B80,0) | C23: Fixed per module | F23: Cost primary cooling loop | G23: Conditional logic for Primary loop piping | H23: 2. Module Capex!B24 - SUBTOTAL: DTC COOLING
A24: SUBTOTAL: DTC COOLING | B24: =SUM(B19:B23) | F24: Subtotal DTC cooling costs | G24: Sum of component values for SUBTOTAL: DTC COOLING | H24: 2. Module Capex!B60 - Applied to base infrastructure; 2. Module Capex!B63 - Base infrastructure; 6. System Capex!B15 - Cooling system
A26: IMMERSION COOLING | B26: Applies when cooling method = Immersion | F26: Section for immersion-specific equipment | G26: Section header
A27: Immersion tanks | B27: =IF(B6="Single-Phase Immersion",B7*'11. Reference Data'!B83,IF(B6="Two-Phase Immersion",B7*'11. Reference Data'!B84,0)) | C27: Racks × tank cost | F27: Cost immersion cooling vessels | G27: Conditional logic for Immersion tanks | H27: 2. Module Capex!B30 - SUBTOTAL: IMMERSION COOLING
A28: Dielectric fluid (initial fill) | B28: =IF(B6="Single-Phase Immersion",B7*'11. Reference Data'!B87*'11. Reference Data'!B85,IF(B6="Two-Phase Immersion",B7*'11. Reference Data'!B88*'11. Reference Data'!B86,0)) | C28: Racks × volume × £/litre | F28: Cost cooling fluid initial fill | G28: Conditional logic for Dielectric fluid (initial fill)
A29: Fluid management system | B29: =IF(OR(B6="Single-Phase Immersion",B6="Two-Phase Immersion"),'11. Reference Data'!B89,0) | C29: Fixed per module | F29: Cost cooling fluid initial fill | G29: Conditional logic for Fluid management system | H29: 2. Module Capex!B30 - SUBTOTAL: IMMERSION COOLING
A30: SUBTOTAL: IMMERSION COOLING | B30: =SUM(B27:B29) | F30: Subtotal immersion cooling costs | G30: Sum of component values for SUBTOTAL: IMMERSION COOLING | H30: 2. Module Capex!B60 - Applied to base infrastructure; 2. Module Capex!B63 - Base infrastructure; 6. System Capex!B15 - Cooling system
A32: POWER DISTRIBUTION
A33: Rack PDUs | B33: =B7*'11. Reference Data'!B92 | C33: Racks × £3,000/rack | F33: Cost power distribution per rack | G33: Calculated from upstream values for Rack PDUs | H33: 2. Module Capex!B36 - SUBTOTAL: POWER
A34: Module power distribution | B34: =B9*'11. Reference Data'!B93 | C34: IT kW × £180/kW | F34: Cost module-level electrical | G34: Calculated from upstream values for Module power distribution
A35: Electrical panels & switchgear | B35: ='11. Reference Data'!B94 | C35: Fixed per module | F35: Cost electrical switching equipment | G35: Pulls value from 11. Reference Data!B94 | H35: 2. Module Capex!B36 - SUBTOTAL: POWER
A36: SUBTOTAL: POWER | B36: =SUM(B33:B35) | F36: Subtotal power distribution costs | G36: Sum of component values for SUBTOTAL: POWER | H36: 2. Module Capex!B63 - Base infrastructure; 6. System Capex!B16 - Power distribution
A38: THERMAL INTEGRATION
A39: Primary heat exchanger (base) | B39: ='11. Reference Data'!B97 | C39: Fixed per module | F39: Cost thermal interface equipment | G39: Pulls value from 11. Reference Data!B97 | H39: 2. Module Capex!B43 - SUBTOTAL: THERMAL
A40: Heat exchanger (capacity scaling) | B40: =B10*'11. Reference Data'!B98 | C40: Thermal kW × £25/kW | F40: Cost thermal interface equipment | G40: Calculated from upstream values for Heat exchanger (capacity scaling)
A41: Thermal integration skid | B41: ='11. Reference Data'!B99 | C41: Fixed per module | F41: Cost heat delivery infrastructure | G41: Pulls value from 11. Reference Data!B99
A42: Instrumentation & sensors | B42: ='11. Reference Data'!B100 | C42: Fixed per module | F42: Cost monitoring equipment | G42: Pulls value from 11. Reference Data!B100 | H42: 2. Module Capex!B43 - SUBTOTAL: THERMAL
A43: SUBTOTAL: THERMAL | B43: =SUM(B39:B42) | F43: Subtotal thermal integration costs | G43: Sum of component values for SUBTOTAL: THERMAL | H43: 2. Module Capex!B63 - Base infrastructure; 6. System Capex!B17 - Thermal integration
A45: MONITORING & CONTROLS
A46: BMS base system | B46: ='11. Reference Data'!B103 | C46: Fixed per module | F46: Cost building management system | G46: Pulls value from 11. Reference Data!B103 | H46: 2. Module Capex!B49 - SUBTOTAL: MONITORING
A47: Per-rack monitoring | B47: =B7*'11. Reference Data'!B104 | C47: Racks × £500/rack | F47: Cost per-rack monitoring | G47: Calculated from upstream values for Per-rack monitoring
...

Sheet 3. Module Opex
A1: MODULE OPEX | F1: Intent | G1: Explanation | H1: Dependents
A2: Annual operating expenditure for a single digital boiler module | F2: Model parameter | G2: Row label only
A4: ELECTRICITY COSTS (TRIBE BEARS) | F4: Financial input or calculation
A5: Electricity rate (£/kWh) | B5: 0.18 | D5: Industrial electricity rate | F5: Set electricity cost assumption | G5: Input parameter: Electricity rate (£/kWh) | H5: 3. Module Opex!B7 - Infrastructure power cost (£/yr); 3. Module Opex!B9 - Heat pump electricity (£/yr); 7. System Opex!B34 - Electricity rate (£/kWh)
A6: Infrastructure power (from PUE) | B6: ='0. Rack Profile'!B23-1 | C6: PUE contribution - 1 | D6: Pumps, controls, BMS, lighting (~5%) | F6: Calculate cooling/support power draw | G6: Formula: Infrastructure power (from PUE) | H6: 3. Module Opex!B7 - Infrastructure power cost (£/yr)
A7: Infrastructure power cost (£/yr) | B7: ='1. Module Criteria'!B5*B6*'1. Module Criteria'!B23*B5*'1. Module Criteria'!B7 | D7: IT kW × 5% × hours × £/kWh × util | F7: Calculate cooling/support power draw | G7: Formula: Infrastructure power cost (£/yr) | H7: 3. Module Opex!B10 - SUBTOTAL: ELECTRICITY
A9: Heat pump electricity (£/yr) | B9: =IF('1. Module Criteria'!B15=1,('1. Module Criteria'!B21/'1. Module Criteria'!B17)*'1. Module Criteria'!B23*'1. Module Criteria'!B7*B5,0) | D9: (HP kWth ÷ COP) × hours × util × £/kWh | F9: Model heat pump operating expense | G9: Conditional logic for Heat pump electricity (£/yr) | H9: 3. Module Opex!B10 - SUBTOTAL: ELECTRICITY
A10: SUBTOTAL: ELECTRICITY | B10: =B7+B9 | F10: Subtotal electricity costs | G10: Calculated from upstream values for SUBTOTAL: ELECTRICITY | H10: 3. Module Opex!B29 - TOTAL MODULE OPEX (£/yr); 7. System Opex!B14 - Electricity (infra + HP)
A12: Note: Tenant rack power is pass-through (not included above) | F12: Model parameter | G12: Row label only
A14: MAINTENANCE & INSURANCE
A15: Base maintenance (% of base capex) | B15: 0.03 | F15: Model ongoing maintenance expense | G15: Input parameter: Base maintenance (% of base capex) | H15: 3. Module Opex!B16 - Base maintenance (£/yr)
A16: Base maintenance (£/yr) | B16: ='2. Module Capex'!B63*B15 | F16: Model ongoing maintenance expense | G16: Formula: Base maintenance (£/yr) | H16: 3. Module Opex!B21 - SUBTOTAL: MAINTENANCE & INSURANCE
A17: Heat pump maintenance (% of HP capex) | B17: 0.02 | F17: Model ongoing maintenance expense | G17: Input parameter: Heat pump maintenance (% of HP capex) | H17: 3. Module Opex!B18 - Heat pump maintenance (£/yr)
A18: Heat pump maintenance (£/yr) | B18: =IF('1. Module Criteria'!B15=1,'2. Module Capex'!B53*B17,0) | F18: Model ongoing maintenance expense | G18: Conditional logic for Heat pump maintenance (£/yr) | H18: 3. Module Opex!B21 - SUBTOTAL: MAINTENANCE & INSURANCE
A19: Insurance (% of total capex) | B19: 0.01 | F19: Model insurance expense | G19: Input parameter: Insurance (% of total capex) | H19: 3. Module Opex!B20 - Insurance (£/yr)
A20: Insurance (£/yr) | B20: ='2. Module Capex'!B66*B19 | F20: Model insurance expense | G20: Formula: Insurance (£/yr) | H20: 3. Module Opex!B21 - SUBTOTAL: MAINTENANCE & INSURANCE
A21: SUBTOTAL: MAINTENANCE & INSURANCE | B21: =B16+B18+B20 | F21: Subtotal maintenance and insurance | G21: Calculated from upstream values for SUBTOTAL: MAINTENANCE & INSURANCE | H21: 3. Module Opex!B29 - TOTAL MODULE OPEX (£/yr); 7. System Opex!B15 - Maintenance & insurance
A23: OTHER OPERATING COSTS
A24: Site lease/licence (£/yr) | B24: 15000 | D24: Payment to industrial host (if any) | F24: Model overhead operating expenses | G24: Input assumption: Site lease/licence (£/yr) | H24: 3. Module Opex!B27 - SUBTOTAL: OTHER
A25: Remote monitoring & NOC (£/yr) | B25: 12000 | D25: 24/7 monitoring, allocated headcount | F25: Model overhead operating expenses | G25: Input assumption: Remote monitoring & NOC (£/yr)
A26: Connectivity & admin (£/yr) | B26: 8000 | F26: Model overhead operating expenses | G26: Input assumption: Connectivity & admin (£/yr) | H26: 3. Module Opex!B27 - SUBTOTAL: OTHER
A27: SUBTOTAL: OTHER | B27: =SUM(B24:B26) | F27: Subtotal other operating costs | G27: Sum of component values for SUBTOTAL: OTHER | H27: 3. Module Opex!B29 - TOTAL MODULE OPEX (£/yr); 7. System Opex!B16 - Other (site, NOC, admin)
A29: TOTAL MODULE OPEX (£/yr) | B29: =B10+B21+B27 | F29: Sum operating costs for profitability analysis | G29: Calculated from upstream values for TOTAL MODULE OPEX (£/yr) | H29: 7. System Opex!B17 - TOTAL PER MODULE
A31: Note: Revenue and P&L calculations moved to System P&L sheet | F31: Model parameter | G31: Row label only
A32: Module-level revenue is theoretical; actual revenue depends on buyer absorption | F32: Model parameter | G32: Row label only

Sheet 4. Module Flow
A1: MODULE FLOW ANALYSIS | F1: Intent | G1: Explanation | H1: Dependents
A2: Hydraulic calculations for a single digital boiler module | F2: Model parameter | G2: Row label only
A4: CONSTANTS
A5: Specific heat of water (kJ/kg·K) | B5: 4.18 | F5: Model parameter | G5: Input parameter: Specific heat of water (kJ/kg·K) | H5: 4. Module Flow!B14 - Mass flow rate (kg/s); 4. Module Flow!B24 - Mass flow rate (kg/s)
A6: Water density (kg/L) | B6: 1 | F6: Model parameter | G6: Flag enabled for Water density (kg/L) | H6: 4. Module Flow!B15 - Volume flow rate (L/s); 4. Module Flow!B25 - Volume flow rate (L/s)
A8: SOURCE LOOP (Servers → Heat Pump) | F8: Model parameter
A9: Thermal power (kWth) | B9: ='1. Module Criteria'!B11 | D9: Heat captured from servers | F9: Pull heat load for flow calculations | G9: Pulls value from 1. Module Criteria!B11 | H9: 4. Module Flow!B14 - Mass flow rate (kg/s)
A10: Inlet temperature (°C) | B10: ='1. Module Criteria'!B12 | F10: Define temperature differential for flow sizing | G10: Pulls value from 1. Module Criteria!B12 | H10: 4. Module Flow!B12 - Outlet temperature (°C)
A11: Source loop ΔT (°C) | B11: =IF('0. Rack Profile'!B17="Direct-to-Chip (DTC)",'11. Reference Data'!E23,IF('0. Rack Profile'!B17="Single-Phase Immersion",'11. Reference Data'!E24,IF('0. Rack Profile'!B17="Two-Phase Immersion",'11. Reference Data'!E25,IF('0. Rack Profile'!B17="Rear Door Heat Exchanger",'11. Reference Data'!E26,'11. Reference Data'!E27)))) | C11: From cooling method (Reference Data) | D11: Temperature drop across HP evaporator | F11: Set temperature drop across heat source | G11: Conditional logic for Source loop ΔT (°C) | H11: 4. Module Flow!B12 - Outlet temperature (°C); 4. Module Flow!B14 - Mass flow rate (kg/s)
A12: Outlet temperature (°C) | B12: =B10-B11 | F12: Define temperature differential for flow sizing | G12: Calculated from upstream values for Outlet temperature (°C)
A14: Mass flow rate (kg/s) | B14: =B9/(B5*B11) | F14: Calculate required fluid flow rate | G14: Calculated from upstream values for Mass flow rate (kg/s) | H14: 4. Module Flow!B15 - Volume flow rate (L/s)
A15: Volume flow rate (L/s) | B15: =B14/B6 | F15: Convert to volumetric flow for pipe sizing | G15: Calculated from upstream values for Volume flow rate (L/s) | H15: 4. Module Flow!B16 - Volume flow rate (m³/hr); 4. Module Flow!B30 - Source loop pipe ID (mm)
A16: Volume flow rate (m³/hr) | B16: =B15*3.6 | F16: Convert to volumetric flow for pipe sizing | G16: Calculated from upstream values for Volume flow rate (m³/hr)
A18: SINK LOOP (Heat Pump → Industrial Partner) | F18: Model parameter
A19: Thermal power delivered (kWth) | B19: ='1. Module Criteria'!B21 | D19: With HP: includes compressor work | F19: Pull heat load for flow calculations | G19: Pulls value from 1. Module Criteria!B21 | H19: 4. Module Flow!B24 - Mass flow rate (kg/s); 4. Module Flow!B37 - Thermal capacity (kWth)
A20: Outlet temperature (°C) | B20: ='1. Module Criteria'!B22 | F20: Define temperature differential for flow sizing | G20: Pulls value from 1. Module Criteria!B22 | H20: 4. Module Flow!B22 - Return temperature (°C); 4. Module Flow!B38 - Delivery temperature (°C)
A21: Sink loop ΔT (°C) | B21: 10 | D21: HP design assumption (process ΔT used in Buyer Profile) | F21: Model parameter | G21: Input parameter: Sink loop ΔT (°C) | H21: 4. Module Flow!B22 - Return temperature (°C); 4. Module Flow!B24 - Mass flow rate (kg/s)
A22: Return temperature (°C) | B22: =B20-B21 | F22: Calculate return water temperature | G22: Calculated from upstream values for Return temperature (°C)
A24: Mass flow rate (kg/s) | B24: =B19/(B5*B21) | F24: Calculate required fluid flow rate | G24: Calculated from upstream values for Mass flow rate (kg/s) | H24: 4. Module Flow!B25 - Volume flow rate (L/s)
A25: Volume flow rate (L/s) | B25: =B24/B6 | F25: Convert to volumetric flow for pipe sizing | G25: Calculated from upstream values for Volume flow rate (L/s) | H25: 4. Module Flow!B26 - Volume flow rate (m³/hr); 4. Module Flow!B31 - Sink loop pipe ID (mm)
A26: Volume flow rate (m³/hr) | B26: =B25*3.6 | F26: Convert to volumetric flow for pipe sizing | G26: Calculated from upstream values for Volume flow rate (m³/hr) | H26: 4. Module Flow!B39 - Flow capacity (m³/hr); 5. Buyer Profile!B30 - Module flow capacity (m³/hr)
A28: PIPE SIZING GUIDANCE
A29: Design velocity (m/s) | B29: 2 | D29: Typical: 1.5-3 m/s | F29: Model parameter | G29: Input parameter: Design velocity (m/s) | H29: 4. Module Flow!B30 - Source loop pipe ID (mm); 4. Module Flow!B31 - Sink loop pipe ID (mm)
A30: Source loop pipe ID (mm) | B30: =SQRT((B15/1000)/(B29*3.14159/4))*1000 | F30: Size piping for required flow | G30: Square root calculation for Source loop pipe ID (mm) | H30: 4. Module Flow!B33 - Source loop - nearest DN
A31: Sink loop pipe ID (mm) | B31: =SQRT((B25/1000)/(B29*3.14159/4))*1000 | F31: Size piping for required flow | G31: Square root calculation for Sink loop pipe ID (mm) | H31: 4. Module Flow!B34 - Sink loop - nearest DN
A33: Source loop - nearest DN | B33: =IF(B30<28,"DN25",IF(B30<36,"DN32",IF(B30<42,"DN40",IF(B30<54,"DN50",IF(B30<68,"DN65",IF(B30<82,"DN80",IF(B30<107,"DN100","DN125+"))))))) | F33: Select standard pipe size | G33: Conditional logic for Source loop - nearest DN
A34: Sink loop - nearest DN | B34: =IF(B31<28,"DN25",IF(B31<36,"DN32",IF(B31<42,"DN40",IF(B31<54,"DN50",IF(B31<68,"DN65",IF(B31<82,"DN80",IF(B31<107,"DN100","DN125+"))))))) | F34: Select standard pipe size | G34: Conditional logic for Sink loop - nearest DN
A36: MODULE HYDRAULIC SUMMARY
A37: Thermal capacity (kWth) | B37: =B19 | F37: Summarise module heat delivery capability | G37: Formula: Thermal capacity (kWth)
A38: Delivery temperature (°C) | B38: =B20 | F38: Summarise module output temperature | G38: Formula: Delivery temperature (°C)
A39: Flow capacity (m³/hr) | B39: =B26 | F39: Summarise module flow capability | G39: Formula: Flow capacity (m³/hr)

Sheet 5. Buyer Profile
A1: BUYER PROFILE | F1: Intent | G1: Explanation | H1: Dependents
A2: Select an industrial process to see system requirements | F2: Model parameter | G2: Row label only
A4: HARDWARE CONFIGURATION
A5: Chipset | B5: ='0. Rack Profile'!B6 | F5: Pull system configuration for context | G5: Pulls value from 0. Rack Profile!B6
A6: Cooling method | B6: ='0. Rack Profile'!B17 | F6: Pull system configuration for context | G6: Pulls value from 0. Rack Profile!B17
A7: GPUs per module | B7: ='0. Rack Profile'!B39 | F7: Pull system configuration for context | G7: Pulls value from 0. Rack Profile!B39
A8: Module IT capacity (kW) | B8: ='0. Rack Profile'!B40 | F8: Pull module size for calculations | G8: Pulls value from 0. Rack Profile!B40
A10: PROCESS SELECTION
A11: Select process | B11: Pasteurisation - Medium | F11: User input to select industrial heat buyer | G11: Text value for Select process | H11: 5. Buyer Profile!B14 - Process name; 5. Buyer Profile!B15 - Size category; 5. Buyer Profile!B16 - Required temperature (°C); 5. Buyer Profile!B17 - Heat demand (kWth); 5. Buyer Profile!B18 - Operating hours/year; 5. Buyer Profile!B19 - Notes; 5. Buyer Profile!B20 - Source:; 5. Buyer Profile!B21 - Source URL:; 5. Buyer Profile!B24 - Process ΔT (°C); 6. System Capex!B10 - Selected buyer profile; ... and 3 more
A13: SELECTED PROCESS PARAMETERS
A14: Process name | B14: =IFERROR(INDEX('12. Process Library'!A:A,MATCH(B11,'12. Process Library'!G:G,0)),"-") | F14: Look up selected process details | G14: Lookup with error handling for Process name
A15: Size category | B15: =IFERROR(INDEX('12. Process Library'!B:B,MATCH(B11,'12. Process Library'!G:G,0)),"-") | F15: Identify process scale | G15: Lookup with error handling for Size category
A16: Required temperature (°C) | B16: =IFERROR(INDEX('12. Process Library'!$C$4:$C$45,MATCH(B11,'12. Process Library'!$G$4:$G$45,0)),"") | F16: Pull buyer's temperature requirement | G16: Lookup with error handling for Required temperature (°C) | H16: 5. Buyer Profile!B32 - Temperature compatible?; 5. Buyer Profile!B69 - Heat pump required?; 5. Buyer Profile!B70 - Temperature lift required (K); 8. System Flow!B14 - Required temperature (°C)
A17: Heat demand (kWth) | B17: =IFERROR(INDEX('12. Process Library'!$D$4:$D$45,MATCH(B11,'12. Process Library'!$G$4:$G$45,0)),"") | F17: Pull buyer's thermal load requirement | G17: Lookup with error handling for Heat demand (kWth) | H17: 5. Buyer Profile!B23 - Annual heat demand (MWh); 5. Buyer Profile!B25 - Required flow rate (m³/hr); 5. Buyer Profile!B33 - Modules needed (thermal); 5. Buyer Profile!B42 - Thermal utilisation (%); 5. Buyer Profile!B47 - Buyer heat absorption (kWth); 6. System Capex!B49 - Capex per kWth delivered (£/kWth); 8. System Flow!B15 - Required thermal load (kWth)
A18: Operating hours/year | B18: =IFERROR(INDEX('12. Process Library'!$E$4:$E$45,MATCH(B11,'12. Process Library'!$G$4:$G$45,0)),"") | F18: Pull buyer's usage pattern | G18: Lookup with error handling for Operating hours/year | H18: 5. Buyer Profile!B23 - Annual heat demand (MWh); 7. System Opex!B33 - Annual operating hours; 8. System Flow!B23 - Annual heat supply (MWh); 9. System P&L!B14 - Operating hours/year; 9. System P&L!B21 - Buyer operating hours/year
A19: Notes | B19: =IFERROR(INDEX('12. Process Library'!F:F,MATCH(B11,'12. Process Library'!G:G,0)),"-") | F19: Pull process context information | G19: Lookup with error handling for Notes
A20: Source: | B20: =IFERROR(INDEX('12. Process Library'!$H$4:$H$45,MATCH(B11,'12. Process Library'!$G$4:$G$45,0)),"") | F20: Reference data provenance | G20: Lookup with error handling for Source:
A21: Source URL: | B21: =IFERROR(INDEX('12. Process Library'!$J$4:$J$45,MATCH(B11,'12. Process Library'!$G$4:$G$45,0)),"") | F21: Reference data provenance | G21: Lookup with error handling for Source URL:
A23: CALCULATED DEMAND
A24: Annual heat demand (MWh) | B24: =B17*B18/1000 | F24: Pull buyer's thermal load requirement | G24: Calculated from upstream values for Annual heat demand (MWh) | H24: 8. System Flow!B17 - Annual heat demand (MWh)
A25: Process ΔT (°C) | B25: =IFERROR(INDEX('12. Process Library'!$I$4:$I$45,MATCH(B11,'12. Process Library'!$G$4:$G$45,0)),10) | C25: From Process Library (default 10 if not found) | D25: Conservative assumption for flow calculation | F25: Pull process temperature differential | G25: Lookup with error handling for Process ΔT (°C) | H25: 5. Buyer Profile!B25 - Required flow rate (m³/hr)
A26: Required flow rate (m³/hr) | B26: =B17/(4.18*B25)*3.6 | F26: Calculate buyer's flow requirement | G26: Calculated from upstream values for Required flow rate (m³/hr) | H26: 5. Buyer Profile!B34 - Modules if flow-constrained (refere...; 5. Buyer Profile!B36 - Flow deficit (m³/hr); 5. Buyer Profile!B37 - Flow ratio (buyer/system); 5. Buyer Profile!B43 - Flow utilisation (%); 5. Buyer Profile!B87 - Flow requirement met?; 8. System Flow!B16 - Required flow rate (m³/hr)
A28: SYSTEM SIZING
A29: Module thermal capacity (kWth) | B29: ='1. Module Criteria'!B21 | F29: Pull single module heat output | G29: Pulls value from 1. Module Criteria!B21 | H29: 5. Buyer Profile!B33 - Modules needed (thermal); 5. Buyer Profile!B40 - System thermal capacity (kWth)
A30: Module delivery temp (°C) | B30: ='1. Module Criteria'!B22 | F30: Pull module output temperature | G30: Pulls value from 1. Module Criteria!B22 | H30: 5. Buyer Profile!B32 - Temperature compatible?
A31: Module flow capacity (m³/hr) | B31: ='4. Module Flow'!B26 | F31: Pull single module flow capacity | G31: Pulls value from 4. Module Flow!B26 | H31: 5. Buyer Profile!B34 - Modules if flow-constrained (refere...; 5. Buyer Profile!B36 - Flow deficit (m³/hr); 5. Buyer Profile!B37 - Flow ratio (buyer/system); 5. Buyer Profile!B41 - System flow capacity (m³/hr)
A33: Temperature compatible? | B33: =IF(B30>=B16,"YES","NO - need higher temp") | F33: Check if system meets buyer temp needs | G33: Conditional logic for Temperature compatible?
A34: Modules needed (thermal) | B34: =ROUNDUP(B17/B29,0) | F34: Calculate modules for thermal demand | G34: Rounded calculation for Modules needed (thermal) | H34: 5. Buyer Profile!B35 - MODULES REQUIRED
A35: Modules if flow-constrained (reference) | B35: =ROUNDUP(B26/B31,0) | C35: Informational only - flow handled via hydraulics | F35: Calculate modules if flow-constrained | G35: Rounded calculation for Modules if flow-constrained (reference)
A36: MODULES REQUIRED | B36: =B34 | C36: Thermal sizing only - flow deficit handled separately | D36: Higher of thermal or flow requirement | F36: Determine final module count for system sizing | G36: Formula: MODULES REQUIRED | H36: 5. Buyer Profile!B36 - Flow deficit (m³/hr); 5. Buyer Profile!B37 - Flow ratio (buyer/system); 5. Buyer Profile!B40 - System thermal capacity (kWth); 5. Buyer Profile!B41 - System flow capacity (m³/hr); 5. Buyer Profile!B64 - Total modules required; 5. Buyer Profile!B65 - Total IT capacity (kW); 5. Buyer Profile!B71 - Heat pump units; 5. Buyer Profile!B72 - Total HP capacity (kWth); 5. Buyer Profile!B76 - Source loop pumps; 5. Buyer Profile!B77 - Sink loop pumps; ... and 9 more
A37: Flow deficit (m³/hr) | B37: =MAX(0,B26-B36*B31) | C37: Buyer flow need minus system flow capacity | F37: Identify shortfall requiring augmentation | G37: Bounded value for Flow deficit (m³/hr) | H37: 5. Buyer Profile!B81 - Flow augmentation pump (m³/hr); 5. Buyer Profile!B82 - Mixing valve required?; 5. Buyer Profile!B84 - Augmentation pumps required; 6. System Capex!B35 - Flow deficit (m³/hr)
A38: Flow ratio (buyer/system) | B38: =IF(B36*B31>0,B26/(B36*B31),0) | C38: >1 means hydraulic augmentation needed | F38: Compare buyer need to system capacity | G38: Conditional logic for Flow ratio (buyer/system) | H38: 5. Buyer Profile!B44 - Hydraulic augmentation needed?
A40: UTILISATION ANALYSIS | H40: 8. System Flow!B22 - System flow capacity (m³/hr)
A41: System thermal capacity (kWth) | B41: =B36*B29 | F41: Calculate total system heat output | G41: Calculated from upstream values for System thermal capacity (kWth) | H41: 5. Buyer Profile!B42 - Thermal utilisation (%); 5. Buyer Profile!B46 - System heat generation (kWth); 5. Buyer Profile!B47 - Buyer heat absorption (kWth); 5. Buyer Profile!B73 - HP electrical demand (kW); 8. System Flow!B32 - Thermal utilisation
A42: System flow capacity (m³/hr) | B42: =B36*B31 | F42: Calculate total system flow | G42: Calculated from upstream values for System flow capacity (m³/hr) | H42: 5. Buyer Profile!B43 - Flow utilisation (%); 5. Buyer Profile!B78 - Total system flow (m³/hr); 5. Buyer Profile!B79 - Header pipe size estimate (DN); 5. Buyer Profile!B86 - Augmented system flow (m³/hr); 8. System Flow!B33 - Flow utilisation
A43: Thermal utilisation (%) | B43: =B17/B41 | F43: Measure how much heat capacity is used | G43: Calculated from upstream values for Thermal utilisation (%) | H43: 8. System Flow!B34 - Binding constraint
A44: Flow utilisation (%) | B44: =IF(B88>0,B26/B88,B26/B42) | C44: Required flow / augmented system flow | F44: Measure how much flow capacity is used | G44: Conditional logic for Flow utilisation (%)
A45: Hydraulic augmentation needed? | B45: =IF(B38>1,"YES - flow ratio "&ROUND(B38,2)&"x","NO") | C45: Flow ratio > 1 means buyer needs more flow than modules provide | F45: Flag if pumps needed for flow boost | G45: Conditional logic for Hydraulic augmentation needed?
A47: HEAT BALANCE
A48: System heat generation (kWth) | B48: =B41 | C48: Total heat from modules | F48: Total heat produced by system | G48: Formula: System heat generation (kWth) | H48: 5. Buyer Profile!B48 - Excess heat (kWth); 5. Buyer Profile!B49 - Excess heat (%); 9. System P&L!B23 - Theoretical heat output (kWth)
...

Sheet 6. System Capex
A1: SYSTEM CAPEX | F1: Intent | G1: Explanation | H1: Dependents
A2: Capital expenditure for complete system serving selected buyer | F2: Model parameter | G2: Row label only
A4: HARDWARE CONFIGURATION
A5: Chipset | B5: ='0. Rack Profile'!B6 | F5: Model parameter | G5: Pulls value from 0. Rack Profile!B6
A6: Cooling method | B6: ='0. Rack Profile'!B17 | F6: Model parameter | G6: Pulls value from 0. Rack Profile!B17
A7: GPUs per module | B7: ='0. Rack Profile'!B39 | F7: Model parameter | G7: Pulls value from 0. Rack Profile!B39
A9: SYSTEM CONFIGURATION
A10: Selected buyer profile | B10: ='5. Buyer Profile'!B11 | F10: Model parameter | G10: Pulls value from 5. Buyer Profile!B11
A11: Modules required | B11: ='5. Buyer Profile'!B36 | F11: Pull module count from buyer sizing | G11: Pulls value from 5. Buyer Profile!B35 | H11: 6. System Capex!B24 - Total module capex; 6. System Capex!B27 - Integration & commissioning; 6. System Capex!B48 - Capex per IT kW (£/kW)
A13: MODULE CAPEX (per unit) | F13: Model parameter
A14: Enclosure & structure | B14: ='2. Module Capex'!B16 | F14: Pull per-module enclosure cost | G14: Pulls value from 2. Module Capex!B16
A15: Cooling system | B15: ='2. Module Capex'!B24+'2. Module Capex'!B30 | C15: DTC or Immersion (whichever applies) | F15: Pull per-module cooling cost | G15: Formula: Cooling system
A16: Power distribution | B16: ='2. Module Capex'!B36 | F16: Pull per-module power cost | G16: Pulls value from 2. Module Capex!B36
A17: Thermal integration | B17: ='2. Module Capex'!B43 | F17: Pull per-module thermal cost | G17: Pulls value from 2. Module Capex!B43
A18: Monitoring & controls | B18: ='2. Module Capex'!B49 | F18: Pull per-module monitoring cost | G18: Pulls value from 2. Module Capex!B49
A19: Cooling method premium | B19: ='2. Module Capex'!B60 | C19: From Rack Profile | F19: Pull cooling technology premium | G19: Pulls value from 2. Module Capex!B60
A20: Heat pump (if enabled) | B20: ='2. Module Capex'!B56 | F20: Pull per-module HP cost | G20: Pulls value from 2. Module Capex!B56
A21: TOTAL PER MODULE | B21: ='2. Module Capex'!B66 | F21: Sum per-module costs for scaling | G21: Pulls value from 2. Module Capex!B66 | H21: 6. System Capex!B24 - Total module capex
A24: Total module capex | B24: =B21*B11 | F24: Calculate all modules cost | G24: Calculated from upstream values for Total module capex | H24: 6. System Capex!B26 - Shared infrastructure (£); 6. System Capex!B43 - Base system capex (excl. rejection)
A25: Shared infrastructure (%) | B25: 0.05 | C25: Common civils, shared services (scales with modules) | F25: Add common infrastructure cost | G25: Input parameter: Shared infrastructure (%) | H25: 6. System Capex!B26 - Shared infrastructure (£)
A26: Shared infrastructure (£) | B26: =B24*B25 | F26: Add common infrastructure cost | G26: Calculated from upstream values for Shared infrastructure (£) | H26: 6. System Capex!B43 - Base system capex (excl. rejection)
A27: Integration & commissioning | B27: =IF(B11>1,25000*(B11-1),0) | C27: £25k per additional module | F27: Add system integration cost | G27: Conditional logic for Integration & commissioning | H27: 6. System Capex!B43 - Base system capex (excl. rejection)
C29: Additional capex for cooling
A30: Rejection capacity required (kWth) | B30: ='5. Buyer Profile'!B54 | F30: Add heat rejection equipment cost | G30: Pulls value from 5. Buyer Profile!B52 | H30: 6. System Capex!B32 - Heat rejection capex
A31: Rejection capex rate (£/kWth) | B31: ='5. Buyer Profile'!B55 | F31: Add heat rejection equipment cost | G31: Pulls value from 5. Buyer Profile!B53 | H31: 6. System Capex!B32 - Heat rejection capex
A32: Heat rejection capex | B32: =IF(B30>0,B30*B31,0) | C32: Sized for 100% rejection (buyer offline scenario) | F32: Add heat rejection equipment cost | G32: Conditional logic for Heat rejection capex | H32: 6. System Capex!B44 - Heat rejection capex
A34: HYDRAULIC AUGMENTATION
A35: Flow deficit (m³/hr) | B35: ='5. Buyer Profile'!B37 | F35: Fluid flow parameter for hydraulic design | G35: Pulls value from 5. Buyer Profile!B36 | H35: 6. System Capex!B38 - Mixing valve + controls; 6. System Capex!B39 - Pipe upsizing allowance
A36: Augmentation pumps required | B36: ='5. Buyer Profile'!B86 | F36: Add flow augmentation cost | G36: Pulls value from 5. Buyer Profile!B84 | H36: 6. System Capex!B37 - Augmentation pump capex
A37: Augmentation pump capex | B37: =B36*'11. Reference Data'!B124*'11. Reference Data'!B120 | C37: Pumps × capacity × £/m³/hr | F37: Add flow augmentation cost | G37: Calculated from upstream values for Augmentation pump capex | H37: 6. System Capex!B40 - SUBTOTAL: HYDRAULIC AUGMENTATION
A38: Mixing valve + controls | B38: =IF(B35>0,'11. Reference Data'!B122,0) | F38: Model parameter | G38: Conditional logic for Mixing valve + controls
A39: Pipe upsizing allowance | B39: =IF(B35>20,B35*'11. Reference Data'!B123,0) | C39: If flow deficit > 20 m³/hr | F39: Model parameter | G39: Conditional logic for Pipe upsizing allowance | H39: 6. System Capex!B40 - SUBTOTAL: HYDRAULIC AUGMENTATION
A40: SUBTOTAL: HYDRAULIC AUGMENTATION | B40: =SUM(B37:B39) | F40: Subtotal flow augmentation costs | G40: Sum of component values for SUBTOTAL: HYDRAULIC AUGMENTATION | H40: 6. System Capex!B45 - Hydraulic augmentation capex
A42: TOTAL SYSTEM CAPEX
A43: Base system capex (excl. rejection) | B43: =B24+B26+B27 | C43: Module + shared + integration costs | F43: Add heat rejection equipment cost | G43: Calculated from upstream values for Base system capex (excl. rejection) | H43: 6. System Capex!B46 - TOTAL SYSTEM CAPEX
A44: Heat rejection capex | B44: =B32 | F44: Add heat rejection equipment cost | G44: Formula: Heat rejection capex | H44: 6. System Capex!B46 - TOTAL SYSTEM CAPEX
A45: Hydraulic augmentation capex | B45: =B40 | F45: Add flow augmentation cost | G45: Formula: Hydraulic augmentation capex | H45: 6. System Capex!B46 - TOTAL SYSTEM CAPEX
